Workbook

Sheet Sheet1
A1: 順豐運單號 | B1: 客戶訂單號 | C1: 訂單狀態 | D1: 下單時間 | E1: 簽收時間 | F1: 訂單總重量 | G1: 包裹總件數 | H1: 簽回單單號 | I1: 寄件方公司 | J1: 寄件方姓名 | K1: 寄件方手機號 | L1: 寄件方固定電話 | M1: 寄件方詳細地址 | N1: 寄件方縣/區 | O1: 寄件方城市 | P1: 寄件方省份 | Q1: 收件方公司 | R1: 收件方姓名 | S1: 收件方手機號 | T1: 收件方固定電話 | U1: 收件方詳細地址 | V1: 收件方城市 | W1: 托寄物 | X1: 下單渠道 | Y1: 下單模塊 | Z1: 寄方備註 | AA1: 付款方式 | AB1: 收件方公司 | AC1: 順豐運單號
A2: SF5117916569145 | B2: Keeta-2026-0701-0001 | C2: 已簽收 | D2: 2026-07-02 11:36:27 | E2: 2026-07-02 19:09 | F2: 2.8 | G2: 1 | J2: keeta | K2: ****57224599 | L2: ****57224599 | M2: ***** 心2808室 | N2: 荔枝角 | O2: 深水埗区 | P2: 香港 | Q2: 721524359 | R2: Jagger | S2: ****95567276 | T2: ****95567276 | U2: ***** 6-30號鋪 | V2: 香港 | W2: POS機+新店禮包 | X2: BSP | Y2: 寄快遞 | AA2: 第三方付 | AB2: =IFERROR(VLOOKUP(Q2&"",對照表!$A:$B,1,FALSE),"") | AC2: =IFERROR(VLOOKUP(Q2&"",對照表!$A:$B,2,FALSE),"")
A3: SF5117916569190 | B3: Keeta-2026-0701-0015 | C3: 已簽收 | D3: 2026-07-02 11:39:14 | E3: 2026-07-02 15:47 | F3: 2.8 | G3: 1 | J3: keeta | K3: ****57224599 | L3: ****57224599 | M3: ***** 心2808室 | N3: 荔枝角 | O3: 深水埗区 | P3: 香港 | Q3: 721522421 | R3: 美味佳（外賣店） | S3: ****61076408 | T3: ****61076408 | U3: ***** 閣G樓1號舖 | V3: 香港 | W3: POS機+新店禮包 | X3: BSP | Y3: 寄快遞 | AA3: 第三方付 | AB3: =IFERROR(VLOOKUP(Q3&"",對照表!$A:$B,1,FALSE),"") | AC3: =IFERROR(VLOOKUP(Q3&"",對照表!$A:$B,2,FALSE),"")
A4: SF5117916569233 | B4: Keeta-2026-0701-0010 | C4: 已簽收 | D4: 2026-07-02 11:41:26 | E4: 2026-07-02 17:28 | F4: 2.8 | G4: 1 | J4: keeta | K4: ****57224599 | L4: ****57224599 | M4: ***** 心2808室 | N4: 荔枝角 | O4: 深水埗区 | P4: 香港 | Q4: 721512392 | R4: E果鮮果店 | S4: ****51378383 | T4: ****51378383 | U4: ***** 市地下D6鋪 | V4: 香港 | W4: POS機+新店禮包 | X4: BSP | Y4: 寄快遞 | AA4: 第三方付 | AB4: =IFERROR(VLOOKUP(Q4&"",對照表!$A:$B,1,FALSE),"") | AC4: =IFERROR(VLOOKUP(Q4&"",對照表!$A:$B,2,FALSE),"")
A5: SF5117916569303 | B5: Keeta-2026-0701-0014 | C5: 已簽收 | D5: 2026-07-02 11:39:03 | E5: 2026-07-02 17:20 | F5: 2.8 | G5: 1 | J5: keeta | K5: ****57224599 | L5: ****57224599 | M5: ***** 心2808室 | N5: 荔枝角 | O5: 深水埗区 | P5: 香港 | Q5: 721527374 | R5: 西貢金雞海南雞GoldenChicken（沙田） | S5: ****61100998 | T5: ****61100998 | U5: ***** eta物資） | V5: 香港 | W5: POS機+新店禮包 | X5: BSP | Y5: 寄快遞 | AA5: 第三方付 | AB5: =IFERROR(VLOOKUP(Q5&"",對照表!$A:$B,1,FALSE),"") | AC5: =IFERROR(VLOOKUP(Q5&"",對照表!$A:$B,2,FALSE),"")
A6: SF5117916569297 | B6: Keeta-2026-0701-0009 | C6: 已簽收 | D6: 2026-07-02 11:41:18 | E6: 2026-07-02 16:45 | F6: 2.8 | G6: 1 | J6: keeta | K6: ****57224599 | L6: ****57224599 | M6: ***** 心2808室 | N6: 荔枝角 | O6: 深水埗区 | P6: 香港 | Q6: 721525425 | R6: 青木食堂 | S6: ****91644427 | T6: ****91644427 | U6: ***** 11樓15室 | V6: 香港 | W6: POS機+新店禮包 | X6: BSP | Y6: 寄快遞 | AA6: 第三方付 | AB6: =IFERROR(VLOOKUP(Q6&"",對照表!$A:$B,1,FALSE),"") | AC6: =IFERROR(VLOOKUP(Q6&"",對照表!$A:$B,2,FALSE),"")
A7: SF5117916569181 | B7: Keeta-2026-0701-0004 | C7: 已簽收 | D7: 2026-07-02 11:37:09 | E7: 2026-07-02 16:57 | F7: 2.8 | G7: 1 | J7: keeta | K7: ****57224599 | L7: ****57224599 | M7: ***** 心2808室 | N7: 荔枝角 | O7: 深水埗区 | P7: 香港 | Q7: 721523398 | R7: MrOppaKitchen | S7: ****94723884 | T7: ****94723884 | U7: ***** 車區餐車一號 | V7: 香港 | W7: POS機+新店禮包 | X7: BSP | Y7: 寄快遞 | AA7: 第三方付 | AB7: =IFERROR(VLOOKUP(Q7&"",對照表!$A:$B,1,FALSE),"") | AC7: =IFERROR(VLOOKUP(Q7&"",對照表!$A:$B,2,FALSE),"")
A8: SF5117916569436 | B8: Keeta-2026-0701-0011 | C8: 已簽收 | D8: 2026-07-02 11:41:37 | E8: 2026-07-02 16:33 | F8: 2.8 | G8: 1 | J8: keeta | K8: ****57224599 | L8: ****57224599 | M8: ***** 心2808室 | N8: 荔枝角 | O8: 深水埗区 | P8: 香港 | Q8: 721529410 | R8: 嚐聚館 | S8: ****69592665 | T8: ****69592665 | U8: ***** 廈15號地鋪 | V8: 香港 | W8: POS機+新店禮包 | X8: BSP | Y8: 寄快遞 | AA8: 第三方付 | AB8: =IFERROR(VLOOKUP(Q8&"",對照表!$A:$B,1,FALSE),"") | AC8: =IFERROR(VLOOKUP(Q8&"",對照表!$A:$B,2,FALSE),"")
A9: SF5117916569163 | B9: Keeta-2026-0701-0003 | C9: 已簽收 | D9: 2026-07-02 11:36:51 | E9: 2026-07-02 19:02 | F9: 2.8 | G9: 1 | J9: keeta | K9: ****57224599 | L9: ****57224599 | M9: ***** 心2808室 | N9: 荔枝角 | O9: 深水埗区 | P9: 香港 | Q9: 721526404 | R9: 香姐美食 | S9: ****56118898 | T9: ****56118898 | U9: ***** 磡明安街8號 | V9: 香港 | W9: POS機+新店禮包 | X9: BSP | Y9: 寄快遞 | AA9: 第三方付 | AB9: =IFERROR(VLOOKUP(Q9&"",對照表!$A:$B,1,FALSE),"") | AC9: =IFERROR(VLOOKUP(Q9&"",對照表!$A:$B,2,FALSE),"")
A10: SF5117916570040 | B10: Keeta-2026-0701-0019 | C10: 已簽收 | D10: 2026-07-02 11:38:27 | E10: 2026-07-02 17:14 | F10: 2.8 | G10: 1 | J10: keeta | K10: ****57224599 | L10: ****57224599 | M10: ***** 心2808室 | N10: 荔枝角 | O10: 深水埗区 | P10: 香港 | Q10: 721517395 | R10: 有膳餐廳（利奧坊） | S10: ****63026760 | T10: ****63026760 | U10: ***** 9-910鋪 | V10: 香港 | W10: POS機+新店禮包 | X10: BSP | Y10: 寄快遞 | AA10: 第三方付 | AB10: =IFERROR(VLOOKUP(Q10&"",對照表!$A:$B,1,FALSE),"") | AC10: =IFERROR(VLOOKUP(Q10&"",對照表!$A:$B,2,FALSE),"")
A11: SF5117916570086 | B11: Keeta-2026-0701-0007 | C11: 已簽收 | D11: 2026-07-02 11:40:59 | E11: 2026-07-02 15:36 | F11: 2.8 | G11: 1 | J11: keeta | K11: ****57224599 | L11: ****57224599 | M11: ***** 心2808室 | N11: 荔枝角 | O11: 深水埗区 | P11: 香港 | Q11: 721530405 | R11: PROSPERITY | S11: ****69933224 | T11: ****69933224 | U11: ***** 6室A4部份 | V11: 香港 | W11: POS機+新店禮包 | X11: BSP | Y11: 寄快遞 | AA11: 第三方付 | AB11: =IFERROR(VLOOKUP(Q11&"",對照表!$A:$B,1,FALSE),"") | AC11: =IFERROR(VLOOKUP(Q11&"",對照表!$A:$B,2,FALSE),"")
A12: SF5117916570156 | B12: Keeta-2026-0701-0002 | C12: 已簽收 | D12: 2026-07-02 11:36:36 | E12: 2026-07-02 19:43 | F12: 2.8 | G12: 1 | J12: keeta | K12: ****57224599 | L12: ****57224599 | M12: ***** 心2808室 | N12: 荔枝角 | O12: 深水埗区 | P12: 香港 | Q12: 721522413 | R12: CatchA首爾炸雞（新浦崗分店） | S12: ****66833331 | T12: ****66833331 | U12: ***** 負責人收到） | V12: 香港 | W12: POS機+新店禮包 | X12: BSP | Y12: 寄快遞 | AA12: 第三方付 | AB12: =IFERROR(VLOOKUP(Q12&"",對照表!$A:$B,1,FALSE),"") | AC12: =IFERROR(VLOOKUP(Q12&"",對照表!$A:$B,2,FALSE),"")
A13: SF5117916570253 | B13: Keeta-2026-0701-0008 | C13: 已簽收 | D13: 2026-07-02 11:41:09 | E13: 2026-07-03 10:40 | F13: 2.8 | G13: 1 | J13: keeta | K13: ****57224599 | L13: ****57224599 | M13: ***** 心2808室 | N13: 荔枝角 | O13: 深水埗区 | P13: 香港 | Q13: 721531396 | R13: 哥哥炸雞（火炭店） | S13: ****92799551 | T13: ****92799551 | U13: ***** B室B9部份 | V13: 香港 | W13: POS機+新店禮包 | X13: BSP | Y13: 寄快遞 | AA13: 第三方付 | AB13: =IFERROR(VLOOKUP(Q13&"",對照表!$A:$B,1,FALSE),"") | AC13: =IFERROR(VLOOKUP(Q13&"",對照表!$A:$B,2,FALSE),"")
... A20: SF5117916570978 | B20: Keeta-2026-0701-0012 | C20: 已簽收 | D20: 2026-07-02 11:38:41 | E20: 2026-07-02 14:33 | F20: 2.8 | G20: 1 | J20: keeta | K20: ****57224599 | L20: ****57224599 | M20: ***** 心2808室 | N20: 荔枝角 | O20: 深水埗区 | P20: 香港 | Q20: 721525415 | R20: 美羅 | S20: ****3210 | T20: ****3210 | U20: ***** OAD KL | V20: 香港 | W20: POS機+新店禮包 | X20: BSP | Y20: 寄快遞 | AA20: 第三方付 | AB20: =IFERROR(VLOOKUP(Q20&"",對照表!$A:$B,1,FALSE),"") | AC20: =IFERROR(VLOOKUP(Q20&"",對照表!$A:$B,2,FALSE),"")
A21: SF5118416341536 | B21: Keeta-2026-0701-0021 | C21: 派送中 | D21: 2026-07-02 11:37:49 | F21: 2.8 | G21: 1 | J21: keeta | K21: ****57224599 | L21: ****57224599 | M21: ***** 心2808室 | N21: 荔枝角 | O21: 深水埗区 | P21: 香港 | Q21: 721540401 | R21: CatchA首爾炸雞（新浦崗分店） | S21: ****28902139 | T21: ****28902139 | U21: ***** 9-20 舖 | V21: 香港 | W21: POS機+新店禮包 | X21: BSP | Y21: 寄快遞 | AA21: 第三方付 | AB21: =IFERROR(VLOOKUP(Q21&"",對照表!$A:$B,1,FALSE),"") | AC21: =IFERROR(VLOOKUP(Q21&"",對照表!$A:$B,2,FALSE),"")
A22: SF5118416341679 | B22: Keeta-2026-0701-0020 | C22: 已簽收 | D22: 2026-07-02 11:37:37 | E22: 2026-07-03 12:22 | F22: 2.8 | G22: 1 | J22: keeta | K22: ****57224599 | L22: ****57224599 | M22: ***** 心2808室 | N22: 荔枝角 | O22: 深水埗区 | P22: 香港 | Q22: 721517401 | R22: COMEBUYTEA(啟德SOGO) | S22: ****28976098 | T22: ****28976098 | U22: ***** G60 舖 | V22: 香港 | W22: POS機+新店禮包 | X22: BSP | Y22: 寄快遞 | AA22: 第三方付 | AB22: =IFERROR(VLOOKUP(Q22&"",對照表!$A:$B,1,FALSE),"") | AC22: =IFERROR(VLOOKUP(Q22&"",對照表!$A:$B,2,FALSE),"")
A23: SF5119115815812 | B23: 58424106156048 | C23: 已簽收 | D23: 2026-07-02 16:58:07 | E23: 2026-07-03 10:40 | F23: 14.5 | G23: 1 | J23: Keeta | K23: ****9568 | M23: ***** 物流中心5樓 | N23: 北区 | O23: 香港 | P23: 香港特别行政区 | Q23: 721531396 | R23: 哥哥炸雞 （火炭店） | S23: ****9551 | T23: ****9551 | U23: ***** B室B9部份 | V23: 香港 | W23: 纸袋【通版】/ 箱出 | X23: ESS-SFTS-OTMS | AA23: 寄付月結 | AB23: =IFERROR(VLOOKUP(Q23&"",對照表!$A:$B,1,FALSE),"") | AC23: =IFERROR(VLOOKUP(Q23&"",對照表!$A:$B,2,FALSE),"")
A24: SF5119115815894 | B24: 58424106156064 | C24: 已簽收 | D24: 2026-07-02 15:15:37 | E24: 2026-07-03 13:44 | F24: 2.36 | G24: 1 | J24: Keeta | K24: ****9568 | M24: ***** 物流中心5樓 | N24: 北区 | O24: 香港 | P24: 香港特别行政区 | Q24: 721518383 | R24: 珍珍泰國菜（德田邨) Jane Thai Food | S24: ****55655926 | T24: ****55655926 | U24: ***** 下M61號檔 | V24: 香港 | W24: 机纸/小票纸 / 包出 | X24: ESS-SFTS-OTMS | AA24: 寄付月結 | AB24: =IFERROR(VLOOKUP(Q24&"",對照表!$A:$B,1,FALSE),"") | AC24: =IFERROR(VLOOKUP(Q24&"",對照表!$A:$B,2,FALSE),"")
A25: SF5119115816298 | B25: 58424106156143 | C25: 已簽收 | D25: 2026-07-02 15:42:49 | E25: 2026-07-03 11:14 | F25: 14.5 | G25: 1 | J25: Keeta | K25: ****9568 | M25: ***** 物流中心5樓 | N25: 北区 | O25: 香港 | P25: 香港特别行政区 | Q25: 721527374 | R25: 西貢金雞海南雞 Golden Chicken （沙田） | S25: ****1100998 | T25: ****1100998 | U25: ***** eta物資） | V25: 香港 | W25: 纸袋【通版】/ 箱出 | X25: ESS-SFTS-OTMS | AA25: 寄付月結 | AB25: =IFERROR(VLOOKUP(Q25&"",對照表!$A:$B,1,FALSE),"") | AC25: =IFERROR(VLOOKUP(Q25&"",對照表!$A:$B,2,FALSE),"")
A26: SF5119115816094 | B26: 58424106156105 | C26: 已簽收 | D26: 2026-07-02 15:42:50 | E26: 2026-07-03 10:05 | F26: 14.5 | G26: 1 | J26: Keeta | K26: ****9568 | M26: ***** 物流中心5樓 | N26: 北区 | O26: 香港 | P26: 香港特别行政区 | Q26: 721526404 | R26: 香姐美食 | S26: ****6118898 | T26: ****6118898 | U26: ***** 磡明安街8號 | V26: 香港 | W26: 纸袋【通版】/ 箱出 | X26: ESS-SFTS-OTMS | AA26: 寄付月結 | AB26: =IFERROR(VLOOKUP(Q26&"",對照表!$A:$B,1,FALSE),"") | AC26: =IFERROR(VLOOKUP(Q26&"",對照表!$A:$B,2,FALSE),"")
A27: SF5119115816340 | B27: 58424106156155 | C27: 已簽收 | D27: 2026-07-02 14:35:24 | E27: 2026-07-03 09:42 | F27: 2.8 | G27: 1 | J27: Keeta | K27: ****9568 | M27: ***** 物流中心5樓 | N27: 北区 | O27: 香港 | P27: 香港特别行政区 | Q27: 496228 | R27: 華星冰室（大埔） | S27: ****26767788 | T27: ****26767788 | U27: ***** 地下31號舖 | V27: 香港 | W27: 机纸/小票纸 / 包出 | X27: ESS-SFTS-OTMS | AA27: 寄付月結 | AB27: =IFERROR(VLOOKUP(Q27&"",對照表!$A:$B,1,FALSE),"") | AC27: =IFERROR(VLOOKUP(Q27&"",對照表!$A:$B,2,FALSE),"")
A28: SF5119115815830 | B28: 58424106156052 | C28: 已簽收 | D28: 2026-07-02 14:17:02 | E28: 2026-07-03 16:45 | F28: 4.45 | G28: 1 | J28: Keeta | K28: ****9568 | M28: ***** 物流中心5樓 | N28: 北区 | O28: 香港 | P28: 香港特别行政区 | Q28: 721519373 | R28: 家之味 Wealthy Poon Choi | S28: ****67654019 | T28: ****67654019 | U28: ***** ng, NT | V28: 香港 | W28: 机纸/小票纸 / 包出 | X28: ESS-SFTS-OTMS | AA28: 寄付月結 | AB28: =IFERROR(VLOOKUP(Q28&"",對照表!$A:$B,1,FALSE),"") | AC28: =IFERROR(VLOOKUP(Q28&"",對照表!$A:$B,2,FALSE),"")
A29: SF5119115816377 | B29: 58424106156161 | C29: 已簽收 | D29: 2026-07-02 15:15:32 | E29: 2026-07-03 13:31 | F29: 1.5 | G29: 1 | J29: Keeta | K29: ****9568 | M29: ***** 物流中心5樓 | N29: 北区 | O29: 香港 | P29: 香港特别行政区 | Q29: 596288 | R29: PizzaHut必勝客(天晉滙) | S29: ****29760076 | T29: ****29760076 | U29: ***** 下G06號舖 | V29: 香港 | W29: 机纸/小票纸 / 包出 | X29: ESS-SFTS-OTMS | AA29: 寄付月結 | AB29: =IFERROR(VLOOKUP(Q29&"",對照表!$A:$B,1,FALSE),"") | AC29: =IFERROR(VLOOKUP(Q29&"",對照表!$A:$B,2,FALSE),"")
A30: SF5119115815973 | B30: 58424106156080 | C30: 已簽收 | D30: 2026-07-02 16:58:06 | E30: 2026-07-03 09:33 | F30: 14.5 | G30: 1 | J30: Keeta | K30: ****9568 | M30: ***** 物流中心5樓 | N30: 北区 | O30: 香港 | P30: 香港特别行政区 | Q30: 721539388 | R30: KPI便當【打工仔首選飯盒滋味便當新鮮健康沙律】 | S30: ****5999941 | T30: ****5999941 | U30: ***** 2期3樓E室 | V30: 香港 | W30: 纸袋【通版】/ 箱出 | X30: ESS-SFTS-OTMS | AA30: 寄付月結 | AB30: =IFERROR(VLOOKUP(Q30&"",對照表!$A:$B,1,FALSE),"") | AC30: =IFERROR(VLOOKUP(Q30&"",對照表!$A:$B,2,FALSE),"")
A31: SF5119115816076 | B31: 58424106156100 | C31: 已簽收 | D31: 2026-07-02 15:42:51 | E31: 2026-07-03 13:30 | F31: 14.5 | G31: 1 | J31: Keeta | K31: ****9568 | M31: ***** 物流中心5樓 | N31: 北区 | O31: 香港 | P31: 香港特别行政区 | Q31: 721540398 | R31: 阿爸韓食店 | S31: ****5668 | T31: ****5668 | U31: ***** 樓地下2B鋪 | V31: 香港 | W31: 纸袋【通版】/ 箱出 | X31: ESS-SFTS-OTMS | AA31: 寄付月結 | AB31: =IFERROR(VLOOKUP(Q31&"",對照表!$A:$B,1,FALSE),"") | AC31: =IFERROR(VLOOKUP(Q31&"",對照表!$A:$B,2,FALSE),"")
A32: SF5119115816261 | B32: 58424106156139 | C32: 已簽收 | D32: 2026-07-02 17:02:19 | E32: 2026-07-03 10:01 | F32: 6.18 | G32: 1 | J32: Keeta | K32: ****9568 | M32: ***** 物流中心5樓 | N32: 北区 | O32: 香港 | P32: 香港特别行政区 | Q32: 468524 | R32: 十三姨酸菜魚(置富都會) | S32: ****28980100 | T32: ****28980100 | U32: ***** 樓751號舖 | V32: 香港 | W32: 机纸/小票纸 / 包出, 封签【通版】/ 扎出 | X32: ESS-SFTS-OTMS | AA32: 寄付月結 | AB32: =IFERROR(VLOOKUP(Q32&"",對照表!$A:$B,1,FALSE),"") | AC32: =IFERROR(VLOOKUP(Q32&"",對照表!$A:$B,2,FALSE),"")
A33: SF5119115816155 | B33: 58424106156116 | C33: 已簽收 | D33: 2026-07-02 14:43:17 | E33: 2026-07-03 13:49 | F33: 1.1 | G33: 1 | J33: Keeta | K33: ****9568 | M33: ***** 物流中心5樓 | N33: 北区 | O33: 香港 | P33: 香港特别行政区 | Q33: 606164 | R33: Terraceinseaside(AIRSIDE) | S33: ****23301398 | T33: ****23301398 | U33: ***** L604號舖 | V33: 香港 | W33: 机纸/小票纸 / 包出 | X33: ESS-SFTS-OTMS | AA33: 寄付月結 | AB33: =IFERROR(VLOOKUP(Q33&"",對照表!$A:$B,1,FALSE),"") | AC33: =IFERROR(VLOOKUP(Q33&"",對照表!$A:$B,2,FALSE),"")
A34: SF5119115815821 | B34: 58424106156051 | C34: 已簽收 | D34: 2026-07-02 16:58:08 | E34: 2026-07-03 12:02 | F34: 14.5 | G34: 1 | J34: Keeta | K34: ****9568 | M34: ***** 物流中心5樓 | N34: 北区 | O34: 香港 | P34: 香港特别行政区 | Q34: 721542349 | R34: Library Restaurant and Bar | S34: ****3650 | T34: ****3650 | U34: ***** 文遜大廈3樓 | V34: 香港 | W34: 纸袋【通版】/ 箱出 | X34: ESS-SFTS-OTMS | AA34: 寄付月結 | AB34: =IFERROR(VLOOKUP(Q34&"",對照表!$A:$B,1,FALSE),"") | AC34: =IFERROR(VLOOKUP(Q34&"",對照表!$A:$B,2,FALSE),"")
... A50: SF5119115815724 | B50: 58424106123276 | C50: 已簽收 | D50: 2026-07-02 15:44:10 | E50: 2026-07-03 13:38 | F50: 29 | G50: 2 | J50: Keeta | K50: ****9568 | M50: ***** 物流中心5樓 | N50: 北区 | O50: 香港 | P50: 香港特别行政区 | Q50: 721512368 | R50: 麥當勞 (樂意居) McDonald&apos;s McDonald&apos;s (Delight Court) | S50: ****27697811 | T50: ****27697811 | U50: ***** 舖及一樓全層 | V50: 香港 | W50: 纸袋【通版】/ 箱出 | X50: ESS-SFTS-OTMS | AA50: 寄付月結 | AB50: =IFERROR(VLOOKUP(Q50&"",對照表!$A:$B,1,FALSE),"") | AC50: =IFERROR(VLOOKUP(Q50&"",對照表!$A:$B,2,FALSE),"")
A51: SF5119115815706 | B51: 58424106123272 | C51: 派送中 | D51: 2026-07-02 17:03:20 | F51: 2.56 | G51: 1 | J51: Keeta | K51: ****9568 | M51: ***** 物流中心5樓 | N51: 北区 | O51: 香港 | P51: 香港特别行政区 | Q51: 721522291 | R51: McDonald&apos;s (Trend Plaza II) | S51: ****51801980 | T51: ****51801980 | U51: ***** 下W32號舖 | V51: 香港 | W51: 塑料袋【大】/ 扎出 | X51: ESS-SFTS-OTMS | AA51: 寄付月結 | AB51: =IFERROR(VLOOKUP(Q51&"",對照表!$A:$B,1,FALSE),"") | AC51: =IFERROR(VLOOKUP(Q51&"",對照表!$A:$B,2,FALSE),"")
A52: SF5119115816012 | B52: 58424106156088 | C52: 已簽收 | D52: 2026-07-02 15:47:43 | E52: 2026-07-03 12:01 | F52: 58 | G52: 4 | J52: Keeta | K52: ****9568 | M52: ***** 物流中心5樓 | N52: 北区 | O52: 香港 | P52: 香港特别行政区 | Q52: 571619 | R52: 麥當勞(樂華)McDonalds | S52: ****23051384 | T52: ****23051384 | U52: ***** 場310號舖 | V52: 香港 | W52: 纸袋【通版】/ 箱出 | X52: ESS-SFTS-OTMS | AA52: 寄付月結 | AB52: =IFERROR(VLOOKUP(Q52&"",對照表!$A:$B,1,FALSE),"") | AC52: =IFERROR(VLOOKUP(Q52&"",對照表!$A:$B,2,FALSE),"")
A53: SF5119115816419 | B53: 58424106156168 | C53: 已簽收 | D53: 2026-07-02 15:42:48 | E53: 2026-07-04 13:28 | F53: 14.5 | G53: 1 | J53: Keeta | K53: ****9568 | M53: ***** 物流中心5樓 | N53: 北区 | O53: 香港 | P53: 香港特别行政区 | Q53: 20260702 | R53: COMEBUYTEA(啟德SOGO) | S53: ****2139 | T53: ****2139 | U53: ***** 9-20 舖 | V53: 香港 | W53: 纸袋【通版】/ 箱出 | X53: ESS-SFTS-OTMS | AA53: 寄付月結 | AB53: =IFERROR(VLOOKUP(Q53&"",對照表!$A:$B,1,FALSE),"") | AC53: =IFERROR(VLOOKUP(Q53&"",對照表!$A:$B,2,FALSE),"")
A54: SF5119115815937 | B54: 58424106156072 | C54: 已簽收 | D54: 2026-07-02 17:01:31 | E54: 2026-07-03 13:06 | F54: 73.22 | G54: 6 | J54: Keeta | K54: ****9568 | M54: ***** 物流中心5樓 | N54: 北区 | O54: 香港 | P54: 香港特别行政区 | Q54: 491642 | R54: 麥當勞(頌安)McDonalds | S54: ****26334380 | T54: ****26334380 | U54: ***** 安商場6號舖 | V54: 香港 | W54: 纸袋【通版】/ 箱出, 机纸/小票纸 / 包出 | X54: ESS-SFTS-OTMS | AA54: 寄付月結 | AB54: =IFERROR(VLOOKUP(Q54&"",對照表!$A:$B,1,FALSE),"") | AC54: =IFERROR(VLOOKUP(Q54&"",對照表!$A:$B,2,FALSE),"")
A55: SF5119115816003 | B55: 58424106156087 | C55: 已簽收 | D55: 2026-07-02 15:42:52 | E55: 2026-07-03 11:08 | F55: 14.5 | G55: 1 | J55: Keeta | K55: ****9568 | M55: ***** 物流中心5樓 | N55: 北区 | O55: 香港 | P55: 香港特别行政区 | Q55: 721529405 | R55: 弼哈海南雞(九龍灣全新推薦, 高質海南雞, 香料全部進口) | S55: ****4119 | T55: ****4119 | U55: ***** 1樓8號鋪 | V55: 香港 | W55: 纸袋【通版】/ 箱出 | X55: ESS-SFTS-OTMS | AA55: 寄付月結 | AB55: =IFERROR(VLOOKUP(Q55&"",對照表!$A:$B,1,FALSE),"") | AC55: =IFERROR(VLOOKUP(Q55&"",對照表!$A:$B,2,FALSE),"")
A56: SF5119115815788 | B56: 58424106156043 | C56: 已簽收 | D56: 2026-07-02 15:44:07 | E56: 2026-07-03 09:00 | F56: 29 | G56: 2 | J56: Keeta | K56: ****9568 | M56: ***** 物流中心5樓 | N56: 北区 | O56: 香港 | P56: 香港特别行政区 | Q56: 596292 | R56: 麥當勞(皇后大道中)McDonalds | S56: ****25418667 | T56: ****25418667 | U56: ***** 2A&2B舖 | V56: 香港 | W56: 纸袋【通版】/ 箱出 | X56: ESS-SFTS-OTMS | AA56: 寄付月結 | AB56: =IFERROR(VLOOKUP(Q56&"",對照表!$A:$B,1,FALSE),"") | AC56: =IFERROR(VLOOKUP(Q56&"",對照表!$A:$B,2,FALSE),"")
A57: SF5119115815964 | B57: 58424106156078 | C57: 已簽收 | D57: 2026-07-02 16:58:05 | E57: 2026-07-03 09:22 | F57: 14.5 | G57: 1 | J57: Keeta | K57: ****9568 | M57: ***** 物流中心5樓 | N57: 北区 | O57: 香港 | P57: 香港特别行政区 | Q57: 721525425 | R57: 青木食堂 | S57: ****4427 | T57: ****4427 | U57: ***** 11樓15室 | V57: 香港 | W57: 纸袋【通版】/ 箱出 | X57: ESS-SFTS-OTMS | AA57: 寄付月結 | AB57: =IFERROR(VLOOKUP(Q57&"",對照表!$A:$B,1,FALSE),"") | AC57: =IFERROR(VLOOKUP(Q57&"",對照表!$A:$B,2,FALSE),"")
A58: SF5119115815919 | B58: 58424106156069 | C58: 已簽收 | D58: 2026-07-02 15:42:52 | E58: 2026-07-03 10:30 | F58: 14.5 | G58: 1 | J58: Keeta | K58: ****9568 | M58: ***** 物流中心5樓 | N58: 北区 | O58: 香港 | P58: 香港特别行政区 | Q58: 721523398 | R58: Mr Oppa Kitchen | S58: ****4723884 | T58: ****4723884 | U58: ***** 車區餐車一號 | V58: 香港 | W58: 纸袋【通版】/ 箱出 | X58: ESS-SFTS-OTMS | AA58: 寄付月結 | AB58: =IFERROR(VLOOKUP(Q58&"",對照表!$A:$B,1,FALSE),"") | AC58: =IFERROR(VLOOKUP(Q58&"",對照表!$A:$B,2,FALSE),"")
A59: SF5119115816182 | B59: 58424106156125 | C59: 已簽收 | D59: 2026-07-02 14:20:09 | E59: 2026-07-03 12:45 | F59: 4.45 | G59: 1 | J59: Keeta | K59: ****9568 | M59: ***** 物流中心5樓 | N59: 北区 | O59: 香港 | P59: 香港特别行政区 | Q59: 608024 | R59: 秋田冰室（調景嶺店） | S59: ****67371100 | T59: ****67371100 | U59: ***** N O,NT | V59: 香港 | W59: 机纸/小票纸 / 包出 | X59: ESS-SFTS-OTMS | AA59: 寄付月結 | AB59: =IFERROR(VLOOKUP(Q59&"",對照表!$A:$B,1,FALSE),"") | AC59: =IFERROR(VLOOKUP(Q59&"",對照表!$A:$B,2,FALSE),"")
A60: SF5119115816058 | B60: 58424106156097 | C60: 已簽收 | D60: 2026-07-02 14:20:10 | E60: 2026-07-03 09:39 | F60: 4.45 | G60: 1 | J60: Keeta | K60: ****9568 | M60: ***** 物流中心5樓 | N60: 北区 | O60: 香港 | P60: 香港特别行政区 | Q60: 491448 | R60: KFC肯德基(家維邨商場) | S60: ****27961211 | T60: ****27961211 | U60: ***** 及LG5號舖 | V60: 香港 | W60: 机纸/小票纸 / 包出 | X60: ESS-SFTS-OTMS | AA60: 寄付月結 | AB60: =IFERROR(VLOOKUP(Q60&"",對照表!$A:$B,1,FALSE),"") | AC60: =IFERROR(VLOOKUP(Q60&"",對照表!$A:$B,2,FALSE),"")
A61: SF5119115816359 | B61: 58424106156157 | C61: 已簽收 | D61: 2026-07-02 15:44:12 | E61: 2026-07-03 13:39 | F61: 29 | G61: 2 | J61: Keeta | K61: ****9568 | M61: ***** 物流中心5樓 | N61: 北区 | O61: 香港 | P61: 香港特别行政区 | Q61: 475184 | R61: 麥當勞(新達廣場II)McDonalds | S61: ****26529900 | T61: ****26529900 | U61: ***** -085號舖 | V61: 香港 | W61: 纸袋【通版】/ 箱出 | X61: ESS-SFTS-OTMS | AA61: 寄付月結 | AB61: =IFERROR(VLOOKUP(Q61&"",對照表!$A:$B,1,FALSE),"") | AC61: =IFERROR(VLOOKUP(Q61&"",對照表!$A:$B,2,FALSE),"")
...

Sheet 對照表
A1: 收件方公司 | B1: 所有順豐運單號
A2: ' | B2: SF0213744738432, SF0218174673442
A3: '20260702 | B3: SF5119115816419
A4: '20260703 | B4: SF5119115816700
A5: '26918328 | B5: SF5119115816313
A6: '27099984 | B6: SF5119115817478
A7: '28753260 | B7: SF5119115816021
A8: '31945010 | B8: SF5119115816482
A9: '389141 | B9: SF5113427653386
A10: '392451 | B10: SF5113427653561
A11: '392471 | B11: SF5116616532983
A12: '395722 | B12: SF5119018988593
... A1159: '97200919 | B1159: SF5119115816207
