Workbook

Sheet 異常件明細
A1: 運單號 | B1: 攬收日期 | C1: 輸出日期 | D1: 最遲回覆日期 | E1: 狀態 | F1: Remarks | G1: 拒收門店ID | H1: 商品編碼 | I1: 商品型號 | J1: 箱數 | K1: 轉寄商家ID | L1: 轉寄商家名稱 | M1: 轉寄電話 | N1: 轉寄地址 | O1: 狀態&更新時間 | P1: 更新資訊 | Q1: 是否簽收 | R1: SF回復
A2: SF5108811069811 | B2: 2026-03-16 | C2: 46098 | D2: {=_xlfn.WORKDAY.INTL(C2,3,"0000001",_xlfn._xlws.FILTER(Sheet1!$A:$A,Sheet1!$C:$C=0))} -> 46101 | E2: 拒收 | F2: 客戶話前幾日送過一箱啦，依家唔需要 | H2: Keeta008 | I2: 紙袋【通版】 | K2: 485153 | L2: 麥當勞 (港灣) McDonald's | M2: 852-25110948 | N2: 香港灣仔港灣道30號新鴻基中心地下G1號店 | O2: 更改新地址 | Q2: 1
A3: SF5123446359100 | B3: 2026-03-13 | C3: 46098 | D3: {=_xlfn.WORKDAY.INTL(C3,3,"0000001",_xlfn._xlws.FILTER(Sheet1!$A:$A,Sheet1!$C:$C=0))} -> 46101 | E3: 未聯繫上 | F3: 上門無此人，電話沒有用戶登記，此單位川婆婆已搬走多年 | H3: Keeta006 | I3: 無紡布【規格四大號】 | K3: 491493 | L3: Four O Five Coffee & Eatery | M3: 852-26500028 | N3: 成業街19-21號成業工業大廈地下2號舖 | O3: 更改新地址 | Q3: 1
A4: SF5123446359861 | B4: 2026-03-13 | C4: 46098 | D4: {=_xlfn.WORKDAY.INTL(C4,3,"0000001",_xlfn._xlws.FILTER(Sheet1!$A:$A,Sheet1!$C:$C=0))} -> 46101 | E4: 拒收 | F4: 店家稱不要 | H4: Keeta006 | I4: 無紡布【規格四大號】 | K4: 577618 | L4: 元氣壽司 (馬鞍山廣場) Genki Sushi | M4: 852-26315953 | N4: 沙田馬鞍山廣場2樓2136-2137舖 | O4: 更改新地址 | Q4: 1
A5: SF5123446359968 | B5: 2026-03-13 | C5: 46098 | D5: {=_xlfn.WORKDAY.INTL(C5,3,"0000001",_xlfn._xlws.FILTER(Sheet1!$A:$A,Sheet1!$C:$C=0))} -> 46101 | E5: 拒收 | F5: 已結業 | H5: Keeta006 | I5: 無紡布【規格四大號】 | K5: 600656 | L5: 元氣壽司 (好爵中心) Genki Sushi | M5: 852-24711366 | N5: 葵湧葵義路2-10號好爵中心地下43號部份及44-48號舖 | O5: 更改新地址 | Q5: 1
A6: SF5123446359076 | B6: 2026-03-13 | C6: 46098 | D6: {=_xlfn.WORKDAY.INTL(C6,3,"0000001",_xlfn._xlws.FILTER(Sheet1!$A:$A,Sheet1!$C:$C=0))} -> 46101 | E6: 未聯繫上 | F6: 客要求轉寄，未提供轉寄地址，現電話無人聽 | H6: Keeta006 | I6: 無紡布【規格四大號】 | K6: 721528332 | L6: CatchA 首爾炸雞 - 觀塘 | M6: 852-53152933 | N6: 香港觀塘駿業街66號巧運工廠大廈11樓A室A1單位 | O6: 更改新地址 | Q6: 1
A7: SF5123446359464 | B7: 2026-03-13 | C7: 46098 | D7: {=_xlfn.WORKDAY.INTL(C7,3,"0000001",_xlfn._xlws.FILTER(Sheet1!$A:$A,Sheet1!$C:$C=0))} -> 46101 | E7: 未聯繫上 | F7: 電話停機，地址不明確 | H7: Keeta005 | I7: 無紡布【規格三中號】 | K7: 721512326 | L7: 豐味炸串 | M7: 852-54863844 | N7: 新界粉嶺百和路88號花都廣場地下77號鋪 | O7: 更改新地址 | Q7: 1
A8: SF5123446359570 | B8: 2026-03-13 | C8: 46098 | D8: {=_xlfn.WORKDAY.INTL(C8,3,"0000001",_xlfn._xlws.FILTER(Sheet1!$A:$A,Sheet1!$C:$C=0))} -> 46101 | E8: 拒收 | F8: 拒收 | H8: Keeta008 | I8: 紙袋【通版】 | K8: 457230 | L8: 麥當勞 (荷李活廣場) McDonald's | M8: 852-29555187 | N8: 九龍鑽石山荷李活廣場二樓216號舖 | O8: 更改新地址 | Q8: 1
A9: SF5123446357341 | B9: 2026-03-13 | C9: 46098 | D9: {=_xlfn.WORKDAY.INTL(C9,3,"0000001",_xlfn._xlws.FILTER(Sheet1!$A:$A,Sheet1!$C:$C=0))} -> 46101 | E9: 拒收 | F9: 客人表示沒有訂購該貨品 | H9: Keeta006 | I9: 無紡布【規格四大號】 | K9: 721540327 | L9: 五豐行(上環店) | M9: 852-54764764 | N9: 皇后大道西60號地下五豐行 | O9: 更改新地址3.20 | Q9: 1
A10: SF5123446359094 | B10: 2026-03-13 | C10: 46098 | D10: {=_xlfn.WORKDAY.INTL(C10,3,"0000001",_xlfn._xlws.FILTER(Sheet1!$A:$A,Sheet1!$C:$C=0))} -> 46101 | E10: 拒收 | F10: 不需要 | H10: Keeta005 | I10: 無紡布【規格三中號】 | K10: 721522309 | L10: 媽子美點 (廿四小時都可以嗌點心食! | M10: 852-26682226 | N10: 香港粉嶺和豐街21號 | O10: 更改新地址 | Q10: 1
A11: SF5123446359419 | B11: 2026-03-13 | C11: 46098 | D11: {=_xlfn.WORKDAY.INTL(C11,3,"0000001",_xlfn._xlws.FILTER(Sheet1!$A:$A,Sheet1!$C:$C=0))} -> 46101 | E11: 拒收 | F11: 客人表示沒有訂購該貨品 | H11: Keeta006 | I11: 無紡布【規格四大號】 | K11: 721537338 | L11: 五豐行(土瓜灣店) | M11: 852-55847120 | N11: 九龍土瓜灣九龍城道34-40號鴻英大廈地下D1,D2舖 | O11: 更改新地址3.20 | Q11: 1
A12: SF5123446359834 | B12: 2026-03-13 | C12: 46098 | D12: {=_xlfn.WORKDAY.INTL(C12,3,"0000001",_xlfn._xlws.FILTER(Sheet1!$A:$A,Sheet1!$C:$C=0))} -> 46101 | E12: 拒收 | F12: 收方公司已結業 | H12: Keeta006 | I12: 無紡布【規格四大號】 | K12: 721445381 | L12: 魔記車仔麵 | M12: 852-98898814 | N12: 九龍長沙灣福榮街218號美居中心地下50號舖 | O12: 更改新地址 | Q12: 1
A13: SF5123446359870 | B13: 2026-03-13 | C13: 46098 | D13: {=_xlfn.WORKDAY.INTL(C13,3,"0000001",_xlfn._xlws.FILTER(Sheet1!$A:$A,Sheet1!$C:$C=0))} -> 46101 | E13: 拒收 | F13: 客戶太多佢收 | H13: Keeta005 | I13: 無紡布【規格三中號】 | K13: 721532354 | L13: 五豐行(沙田店) | M13: 852-55239285 | N13: 新界沙田乙明邨街9號，乙明邨街市27號攤位 | O13: 更改新地址3.20 | Q13: 1
... A19: SF5123446359482 | B19: 2026-03-13 | C19: 46098 | D19: {=_xlfn.WORKDAY.INTL(C19,3,"0000001",_xlfn._xlws.FILTER(Sheet1!$A:$A,Sheet1!$C:$C=0))} -> 46101 | E19: 拒收 | F19: 不需要 | H19: Keeta006 | I19: 無紡布【規格四大號】 | K19: 462057 | L19: Cyprium Cafe（食過仲想食，鋸扒意粉下午茶） | M19: 852-97578959 | N19: 石門安群街3號京瑞廣場1期1樓133-135號舖 | O19: 更改新地址3.20 | Q19: 1
A20: SF0223840052943 | B20: 46098 | C20: 46101 | D20: {=_xlfn.WORKDAY.INTL(C20,3,"0000001",_xlfn._xlws.FILTER(Sheet1!$A:$A,Sheet1!$C:$C=0))} -> 46105 | E20: 電話號碼異常 | H20: Keeta013 | I20: 機紙/小票紙 | K20: 721429323 | L20: 韓鍋酒舍 | M20: 852-23822178 | N20: 聯發街18號地舖 | O20: 更改新地址3.20 | Q20: 1
A21: SF0223840052998 | B21: 46098 | C21: 46101 | D21: {=_xlfn.WORKDAY.INTL(C21,3,"0000001",_xlfn._xlws.FILTER(Sheet1!$A:$A,Sheet1!$C:$C=0))} -> 46105 | E21: 未聯繫上 | H21: Keeta013 | I21: 機紙/小票紙 | K21: 721421363 | L21: 小蜜蜂炸雞 (新蒲崗店） | M21: 852-60776246 | N21: 九龍新蒲崗六合街25號嘉時工業大廈5樓A2室（G單位） | O21: 更改新地址3.20 | P21: 3.20 成功派送至原收方, 所以沒有轉寄至新商家 | Q21: 1
A22: SF5123144666527 | B22: 46099 | C22: 46101 | D22: {=_xlfn.WORKDAY.INTL(C22,3,"0000001",_xlfn._xlws.FILTER(Sheet1!$A:$A,Sheet1!$C:$C=0))} -> 46105 | E22: 地址不詳 | H22: Keeta008 | I22: 紙袋【通版】 | K22: 721514324 | L22: Powersellers Worldwide Limited | M22: 852-92600825 | N22: FLAT/RM P BLK1 14/F KINGSWIN INDUSTRIAL BUILDING 32 LEI MUK ROAD KWAI CHUNG NT | O22: 更改新地址3.20 | Q22: 1
A23: SF5123144662962 | B23: 46099 | C23: 46101 | D23: {=_xlfn.WORKDAY.INTL(C23,3,"0000001",_xlfn._xlws.FILTER(Sheet1!$A:$A,Sheet1!$C:$C=0))} -> 46105 | E23: 拒收 | H23: Keeta008 | I23: 紙袋【通版】 | K23: 721523342 | L23: 多多屋~無雙酒業 | M23: 852-55206988 | N23: SHOP NO.5,G/F KAI HEI LAND BUILDING385CASTLE PEAK ROAD TUEN MUN HK | O23: 更改新地址3.20 | Q23: 1
A24: SF5123535243572 | B24: 2026-03-20 | C24: 46104 | D24: {=_xlfn.WORKDAY.INTL(C24,3,"0000001",_xlfn._xlws.FILTER(Sheet1!$A:$A,Sheet1!$C:$C=0))} -> 46107 | E24: 電話號碼異常 | H24: Keeta005 | I24: 無紡布【規格三中號】 | K24: 478169 | L24: 越風味 | M24: 852-69961760 | N24: 砵蘭街108號地舖 | O24: 更改新地址4.1 | P24: 關聯新單號SF6016503210535 | Q24: 1
A25: SF0223700225714 | B25: 2026-03-19 | C25: 46104 | D25: {=_xlfn.WORKDAY.INTL(C25,3,"0000001",_xlfn._xlws.FILTER(Sheet1!$A:$A,Sheet1!$C:$C=0))} -> 46107 | E25: 電話號碼異常 | H25: Keeta008 | I25: 紙袋【通版】 | K25: 721533349 | L25: Bunlulu Vibe | M25: 852-94358876 | N25: 香港上環荷李活道186-190A號荷李活大廈地下B1鋪 | O25: 更改新地址3.25 | Q25: 1
A26: SF5123535245641 | B26: 2026-03-20 | C26: 46104 | D26: {=_xlfn.WORKDAY.INTL(C26,3,"0000001",_xlfn._xlws.FILTER(Sheet1!$A:$A,Sheet1!$C:$C=0))} -> 46107 | E26: 未聯繫上 | H26: Keeta005 | I26: 無紡布【規格三中號】 | K26: 721520312 | L26: 聚湘緣 | M26: 852-69233880 | N26: 嘉圖工廠大廈1樓D室18號廚房 | O26: 更改新地址3.25 | Q26: 1
A27: SF5123535243590 | B27: 2026-03-20 | C27: 46104 | D27: {=_xlfn.WORKDAY.INTL(C27,3,"0000001",_xlfn._xlws.FILTER(Sheet1!$A:$A,Sheet1!$C:$C=0))} -> 46107 | E27: 拒收 | H27: Keeta005 | I27: 無紡布【規格三中號】 | K27: 402352 | L27: 泰亞萊【泰國菜天花板 必食人氣套餐】 | M27: 852-28161138 | N27: 紅磡庇利街32號地舖 | O27: 更改新地址3.25 | Q27: 1
A28: SF5123535243342 | B28: 2026-03-20 | C28: 46104 | D28: {=_xlfn.WORKDAY.INTL(C28,3,"0000001",_xlfn._xlws.FILTER(Sheet1!$A:$A,Sheet1!$C:$C=0))} -> 46107 | E28: 電話號碼異常 | H28: Keeta005 | I28: 無紡布【規格三中號】 | K28: 484763 | L28: LeeLaksa(上環)|招牌叻沙 | M28: 852-22658999 | N28: 上環皇后大道中302號地舖 | O28: 更改新地址3.25 | Q28: 1
A29: SF5123535243157 | B29: 2026-03-20 | C29: 46104 | D29: {=_xlfn.WORKDAY.INTL(C29,3,"0000001",_xlfn._xlws.FILTER(Sheet1!$A:$A,Sheet1!$C:$C=0))} -> 46107 | E29: 拒收 | H29: Keeta005 | I29: 無紡布【規格三中號】 | K29: 606178 | L29: 7-Eleven（沙田禾輋邨）1409 | M29: 852-26045178 | N29: 新界沙田禾輋邨禾輋廣場地下G3及G4號舖 | O29: 更改新地址3.25 | Q29: 1
A30: SF5125742080586 | B30: 2026-03-20 | C30: 46104 | D30: {=_xlfn.WORKDAY.INTL(C30,3,"0000001",_xlfn._xlws.FILTER(Sheet1!$A:$A,Sheet1!$C:$C=0))} -> 46107 | E30: 未聯繫上 | L30: 不變 | M30: 93504837 | N30: 不變 | O30: 24/3/2026 | P30: 商家一般下午在，上午無人接收快遞 | Q30: 1
A31: SF0223700225705 | B31: 2026-03-19 | C31: 46104 | D31: {=_xlfn.WORKDAY.INTL(C31,3,"0000001",_xlfn._xlws.FILTER(Sheet1!$A:$A,Sheet1!$C:$C=0))} -> 46107 | E31: 未聯繫上 | H31: Keeta008 | I31: 紙袋【通版】 | K31: 721524342 | L31: Slow Cow | M31: 85291047240 | N31: 中環威靈頓街112-114號新威大廈地下C號舖 | O31: 更改新地址3.25 | Q31: 1
A32: SF5123535245429 | B32: 2026-03-20 | C32: 46104 | D32: {=_xlfn.WORKDAY.INTL(C32,3,"0000001",_xlfn._xlws.FILTER(Sheet1!$A:$A,Sheet1!$C:$C=0))} -> 46107 | E32: 拒收 | H32: Keeta005 | I32: 無紡布【規格三中號】 | K32: 484072 | L32: 韓味舍 (觀塘)滿滿韓意,可能係CP值最高韓國料理 | M32: 852-98218902 | N32: 九龍觀塘駿業街66號巧運工業大廈11樓C室D部份 | O32: 更改新地址3.25 | Q32: 1
A33: SF0225320244276 | B33: 2026-03-19 | C33: 46104 | D33: {=_xlfn.WORKDAY.INTL(C33,3,"0000001",_xlfn._xlws.FILTER(Sheet1!$A:$A,Sheet1!$C:$C=0))} -> 46107 | E33: 未聯繫上 | L33: 不變 | M33: 63398664 | N33: 不變 | O33: 更新收件電話, 收方表示放門口就可以了3.24 | Q33: 1
A34: SF5123144662722 | B34: 2026-03-18 | C34: 46106 | D34: {=_xlfn.WORKDAY.INTL(C34,3,"0000001",_xlfn._xlws.FILTER(Sheet1!$A:$A,Sheet1!$C:$C=0))} -> 46109 | E34: 收方要求轉寄 | F34: 收方稱寄方填錯地址，正確為地址為偉業街22號7樓E室R2 | L34: 不變 | M34: 不變 | N34: 觀塘偉業街22號7樓E室R2 | O34: 更改新地址3.25 | Q34: 1
A35: SF5125001441311 | B35: 2026-03-23 | C35: 46106 | D35: {=_xlfn.WORKDAY.INTL(C35,3,"0000001",_xlfn._xlws.FILTER(Sheet1!$A:$A,Sheet1!$C:$C=0))} -> 46109 | E35: 拒收 | H35: Keeta008 | I35: 紙袋【通版】 | K35: 462144 | L35: PretAManger(AIATower友邦廣場) | M35: 852-25457908 | N35: 北角電氣道183號友邦廣場地下S1號鋪 | O35: 更改新地址3.26 | Q35: 1
A36: SF5125645959615 | B36: 46106 | C36: 46107 | D36: {=_xlfn.WORKDAY.INTL(C36,3,"0000001",_xlfn._xlws.FILTER(Sheet1!$A:$A,Sheet1!$C:$C=0))} -> 46111 | E36: 收方要求轉寄 | L36: 不變 | M36: 不變 | N36: 九龍九龍灣德福廣場一期F28號舖 | O36: 更改新地址3.26 | Q36: 1
A37: SF0221880676320 | B37: 46105 | C37: 46107 | D37: {=_xlfn.WORKDAY.INTL(C37,3,"0000001",_xlfn._xlws.FILTER(Sheet1!$A:$A,Sheet1!$C:$C=0))} -> 46111 | E37: 未聯繫上 | L37: 不變 | M37: 65860478 | N37: 九龍觀塘成業街19-21號成業工業大廈1樓22室 | O37: 更改新地址3.26 | Q37: 1
A38: SF5133475573365 | B38: 2026-03-24 | C38: 46107 | D38: {=_xlfn.WORKDAY.INTL(C38,3,"0000001",_xlfn._xlws.FILTER(Sheet1!$A:$A,Sheet1!$C:$C=0))} -> 46111 | E38: 未聯繫上 | H38: Keeta008 | I38: 紙袋【通版】 | K38: 584387 | L38: MOSCafé(戲曲中心) | M38: 852-25504169 | N38: 尖沙咀柯士甸道西88號戲曲中心地庫二樓02鋪 | O38: 更改新地址3.26 | Q38: 1
A39: SF5125464786702 | B39: 2026-03-24 | C39: 46107 | D39: {=_xlfn.WORKDAY.INTL(C39,3,"0000001",_xlfn._xlws.FILTER(Sheet1!$A:$A,Sheet1!$C:$C=0))} -> 46111 | E39: 未聯繫上 | I39: POS機+新店禮包 | L39: 不變 | M39: 不變 | N39: 不變 | O39: 30/3/2026 | P39: 寄方表示放門口OK | Q39: 1
A40: SF5133475573286 | B40: 2026-03-24 | C40: 46107 | D40: {=_xlfn.WORKDAY.INTL(C40,3,"0000001",_xlfn._xlws.FILTER(Sheet1!$A:$A,Sheet1!$C:$C=0))} -> 46111 | E40: 未聯繫上 | H40: Keeta008 | I40: 紙袋【通版】 | K40: 597565 | L40: MOSCafé(奧海城) | M40: 852-29972879 | N40: 大角咀海輝道11號奧海城一期UG樓UG23&25號舖 | O40: 更改新地址3.26 | Q40: 1
A41: SF5125294610376 | B41: 2026-03-27 | C41: 46111 | D41: {=_xlfn.WORKDAY.INTL(C41,3,"0000001",_xlfn._xlws.FILTER(Sheet1!$A:$A,Sheet1!$C:$C=0))} -> 46114 | E41: 拒收 | G41: 484893 | H41: Keeta006 | I41: 無紡布【規格四大號】 | J41: 1 | K41: 823020 | L41: 東海堂(銅鑼灣蘭芳道)AromeBakery | M41: 852-29819906 | N41: 香港銅鑼灣蘭芳道1號 地下1號舖 | O41: 更改新地址3.31 | Q41: 1
A42: SF5125294614082 | B42: 2026-03-27 | C42: 46111 | D42: {=_xlfn.WORKDAY.INTL(C42,3,"0000001",_xlfn._xlws.FILTER(Sheet1!$A:$A,Sheet1!$C:$C=0))} -> 46114 | E42: 拒收 | G42: 491486 | H42: Keeta006 | I42: 無紡布【規格四大號】 | J42: 1 | K42: 865749 | L42: 東海堂(將軍澳廣場)AromeBakery | M42: 852-35684475 | N42: 新界將軍澳唐德街1號將軍澳廣場1樓1-078號舖 | O42: 更改新地址3.31 | Q42: 1
A43: SF0227080854043 | B43: 2026-03-26 | C43: 46111 | D43: {=_xlfn.WORKDAY.INTL(C43,3,"0000001",_xlfn._xlws.FILTER(Sheet1!$A:$A,Sheet1!$C:$C=0))} -> 46114 | E43: 未聯繫上 | G43: 721530351 | I43: POS機+新店禮包 | J43: 1 | K43: 不變 | L43: 不變 | M43: 98798128 | N43: 太古城中心2期B1樓APITATKS-04號鋪 | O43: 更改新地址4.2 | Q43: 1
A44: SF5125294610385 | B44: 2026-03-27 | C44: 46111 | D44: {=_xlfn.WORKDAY.INTL(C44,3,"0000001",_xlfn._xlws.FILTER(Sheet1!$A:$A,Sheet1!$C:$C=0))} -> 46114 | E44: 拒收 | G44: 603724 | H44: Keeta008 | I44: 紙袋【通版】 | J44: 1 | K44: 491458 | L44: BrunchClubAlldayBreakfast | M44: 852-25268861 | N44: 蘇豪卑利街70號地下 | O44: 更改新地址3.31 | Q44: 1
A45: SF5125294610233 | B45: 2026-03-27 | C45: 46111 | D45: {=_xlfn.WORKDAY.INTL(C45,3,"0000001",_xlfn._xlws.FILTER(Sheet1!$A:$A,Sheet1!$C:$C=0))} -> 46114 | E45: 拒收 | G45: 471770 | H45: Keeta005 | I45: 無紡布【規格三中號】 | J45: 2 | K45: 468581 | L45: ProteinMatters蛋白質料理所 | M45: 852-68985957 | N45: 2樓Freshlane德輔道西103號29號廚房 | O45: 更改新地址3.31 | Q45: 1
...

Sheet Sheet1
A1: 2026 | B1: 日期類型 | C1: 工作日
A2: 46023 | B2: 星期四 | C2: 0
A3: 46024 | B3: 星期五 | C3: 1
A4: 46025 | B4: 星期六 | C4: 1
A5: 46026 | B5: 星期日 | C5: 0
A6: 46027 | B6: 星期一 | C6: 1
A7: 46028 | B7: 星期二 | C7: 1
A8: 46029 | B8: 星期三 | C8: 1
A9: 46030 | B9: 星期四 | C9: 1
A10: 46031 | B10: 星期五 | C10: 1
A11: 46032 | B11: 星期六 | C11: 1
A12: 46033 | B12: 星期日 | C12: 0
A13: 46034 | B13: 星期一 | C13: 1
... A366: 46387 | B366: 星期四 | C366: 1
